Workbook

Sheet Summary (Non Solo)
A1: TECMO PASSING RECORDS
A2: Most Attempts
A3: =IFERROR(__xludf.DUMMYFUNCTION("query(Passing!A2:P178, ""select * where P = 'No' order by D desc limit 3"",1)"),"POS") -> POS | B3: =IFERROR(__xludf.DUMMYFUNCTION("""COMPUTED_VALUE"""),"Last Name") -> Last Name | C3: =IFERROR(__xludf.DUMMYFUNCTION("""COMPUTED_VALUE"""),"First Name") -> First Name | D3: =IFERROR(__xludf.DUMMYFUNCTION("""COMPUTED_VALUE"""),"ATT") -> ATT | E3: =IFERROR(__xludf.DUMMYFUNCTION("""COMPUTED_VALUE"""),"COMPS") -> COMPS | F3: =IFERROR(__xludf.DUMMYFUNCTION("""COMPUTED_VALUE"""),"COMP %") -> COMP % | G3: =IFERROR(__xludf.DUMMYFUNCTION("""COMPUTED_VALUE"""),"YDS") -> YDS | H3: =IFERROR(__xludf.DUMMYFUNCTION("""COMPUTED_VALUE"""),"AVG YDS") -> AVG YDS | I3: =IFERROR(__xludf.DUMMYFUNCTION("""COMPUTED_VALUE"""),"TD") -> TD | J3: =IFERROR(__xludf.DUMMYFUNCTION("""COMPUTED_VALUE"""),"INT") -> INT | K3: =IFERROR(__xludf.DUMMYFUNCTION("""COMPUTED_VALUE"""),"RATING") -> RATING | L3: =IFERROR(__xludf.DUMMYFUNCTION("""COMPUTED_VALUE"""),"Team") -> Team | M3: =IFERROR(__xludf.DUMMYFUNCTION("""COMPUTED_VALUE"""),"User") -> User | N3: =IFERROR(__xludf.DUMMYFUNCTION("""COMPUTED_VALUE"""),"Season") -> Season | O3: =IFERROR(__xludf.DUMMYFUNCTION("""COMPUTED_VALUE"""),"Year") -> Year | P3: =IFERROR(__xludf.DUMMYFUNCTION("""COMPUTED_VALUE"""),"Solo") -> Solo
A4: =IFERROR(__xludf.DUMMYFUNCTION("""COMPUTED_VALUE"""),"QB") -> QB | B4: =IFERROR(__xludf.DUMMYFUNCTION("""COMPUTED_VALUE"""),"Moon") -> Moon | C4: =IFERROR(__xludf.DUMMYFUNCTION("""COMPUTED_VALUE"""),"Warren") -> Warren | D4: =IFERROR(__xludf.DUMMYFUNCTION("""COMPUTED_VALUE"""),316.0) -> 316 | E4: =IFERROR(__xludf.DUMMYFUNCTION("""COMPUTED_VALUE"""),200.0) -> 200 | F4: =IFERROR(__xludf.DUMMYFUNCTION("""COMPUTED_VALUE"""),63.2) -> 63.2 | G4: =IFERROR(__xludf.DUMMYFUNCTION("""COMPUTED_VALUE"""),6365.0) -> 6365 | H4: =IFERROR(__xludf.DUMMYFUNCTION("""COMPUTED_VALUE"""),20.1) -> 20.1 | I4: =IFERROR(__xludf.DUMMYFUNCTION("""COMPUTED_VALUE"""),80.0) -> 80 | J4: =IFERROR(__xludf.DUMMYFUNCTION("""COMPUTED_VALUE"""),6.0) -> 6 | K4: =IFERROR(__xludf.DUMMYFUNCTION("""COMPUTED_VALUE"""),197.2) -> 197.2 | L4: =IFERROR(__xludf.DUMMYFUNCTION("""COMPUTED_VALUE"""),"HOU") -> HOU | M4: =IFERROR(__xludf.DUMMYFUNCTION("""COMPUTED_VALUE"""),"WB") -> WB | N4: =IFERROR(__xludf.DUMMYFUNCTION("""COMPUTED_VALUE"""),6.0) -> 6 | O4: =IFERROR(__xludf.DUMMYFUNCTION("""COMPUTED_VALUE"""),2011.0) -> 2011 | P4: =IFERROR(__xludf.DUMMYFUNCTION("""COMPUTED_VALUE"""),"No") -> No
A5: =IFERROR(__xludf.DUMMYFUNCTION("""COMPUTED_VALUE"""),"QB") -> QB | B5: =IFERROR(__xludf.DUMMYFUNCTION("""COMPUTED_VALUE"""),"Moon") -> Moon | C5: =IFERROR(__xludf.DUMMYFUNCTION("""COMPUTED_VALUE"""),"Warren") -> Warren | D5: =IFERROR(__xludf.DUMMYFUNCTION("""COMPUTED_VALUE"""),305.0) -> 305 | E5: =IFERROR(__xludf.DUMMYFUNCTION("""COMPUTED_VALUE"""),183.0) -> 183 | F5: =IFERROR(__xludf.DUMMYFUNCTION("""COMPUTED_VALUE"""),60.0) -> 60 | G5: =IFERROR(__xludf.DUMMYFUNCTION("""COMPUTED_VALUE"""),5822.0) -> 5822 | H5: =IFERROR(__xludf.DUMMYFUNCTION("""COMPUTED_VALUE"""),19.0) -> 19 | I5: =IFERROR(__xludf.DUMMYFUNCTION("""COMPUTED_VALUE"""),73.0) -> 73 | J5: =IFERROR(__xludf.DUMMYFUNCTION("""COMPUTED_VALUE"""),11.0) -> 11 | K5: =IFERROR(__xludf.DUMMYFUNCTION("""COMPUTED_VALUE"""),185.4) -> 185.4 | L5: =IFERROR(__xludf.DUMMYFUNCTION("""COMPUTED_VALUE"""),"HOU") -> HOU | M5: =IFERROR(__xludf.DUMMYFUNCTION("""COMPUTED_VALUE"""),"WB") -> WB | N5: =IFERROR(__xludf.DUMMYFUNCTION("""COMPUTED_VALUE"""),10.0) -> 10 | O5: =IFERROR(__xludf.DUMMYFUNCTION("""COMPUTED_VALUE"""),2018.0) -> 2018 | P5: =IFERROR(__xludf.DUMMYFUNCTION("""COMPUTED_VALUE"""),"No") -> No
A6: =IFERROR(__xludf.DUMMYFUNCTION("""COMPUTED_VALUE"""),"QB") -> QB | B6: =IFERROR(__xludf.DUMMYFUNCTION("""COMPUTED_VALUE"""),"Marino") -> Marino | C6: =IFERROR(__xludf.DUMMYFUNCTION("""COMPUTED_VALUE"""),"Dan") -> Dan | D6: =IFERROR(__xludf.DUMMYFUNCTION("""COMPUTED_VALUE"""),277.0) -> 277 | E6: =IFERROR(__xludf.DUMMYFUNCTION("""COMPUTED_VALUE"""),229.0) -> 229 | F6: =IFERROR(__xludf.DUMMYFUNCTION("""COMPUTED_VALUE"""),82.6) -> 82.6 | G6: =IFERROR(__xludf.DUMMYFUNCTION("""COMPUTED_VALUE"""),6743.0) -> 6743 | H6: =IFERROR(__xludf.DUMMYFUNCTION("""COMPUTED_VALUE"""),24.3) -> 24.3 | I6: =IFERROR(__xludf.DUMMYFUNCTION("""COMPUTED_VALUE"""),110.0) -> 110 | J6: =IFERROR(__xludf.DUMMYFUNCTION("""COMPUTED_VALUE"""),0.0) -> 0 | K6: =IFERROR(__xludf.DUMMYFUNCTION("""COMPUTED_VALUE"""),248.1) -> 248.1 | L6: =IFERROR(__xludf.DUMMYFUNCTION("""COMPUTED_VALUE"""),"MIA") -> MIA | M6: =IFERROR(__xludf.DUMMYFUNCTION("""COMPUTED_VALUE"""),"CJ") -> CJ | N6: =IFERROR(__xludf.DUMMYFUNCTION("""COMPUTED_VALUE"""),13.0) -> 13 | O6: =IFERROR(__xludf.DUMMYFUNCTION("""COMPUTED_VALUE"""),2021.0) -> 2021 | P6: =IFERROR(__xludf.DUMMYFUNCTION("""COMPUTED_VALUE"""),"No") -> No
A8: Most Completions
A9: =IFERROR(__xludf.DUMMYFUNCTION("query(Passing!A2:P178, ""select * where P = 'No' order by E desc limit 3"",1)"),"POS") -> POS | B9: =IFERROR(__xludf.DUMMYFUNCTION("""COMPUTED_VALUE"""),"Last Name") -> Last Name | C9: =IFERROR(__xludf.DUMMYFUNCTION("""COMPUTED_VALUE"""),"First Name") -> First Name | D9: =IFERROR(__xludf.DUMMYFUNCTION("""COMPUTED_VALUE"""),"ATT") -> ATT | E9: =IFERROR(__xludf.DUMMYFUNCTION("""COMPUTED_VALUE"""),"COMPS") -> COMPS | F9: =IFERROR(__xludf.DUMMYFUNCTION("""COMPUTED_VALUE"""),"COMP %") -> COMP % | G9: =IFERROR(__xludf.DUMMYFUNCTION("""COMPUTED_VALUE"""),"YDS") -> YDS | H9: =IFERROR(__xludf.DUMMYFUNCTION("""COMPUTED_VALUE"""),"AVG YDS") -> AVG YDS | I9: =IFERROR(__xludf.DUMMYFUNCTION("""COMPUTED_VALUE"""),"TD") -> TD | J9: =IFERROR(__xludf.DUMMYFUNCTION("""COMPUTED_VALUE"""),"INT") -> INT | K9: =IFERROR(__xludf.DUMMYFUNCTION("""COMPUTED_VALUE"""),"RATING") -> RATING | L9: =IFERROR(__xludf.DUMMYFUNCTION("""COMPUTED_VALUE"""),"Team") -> Team | M9: =IFERROR(__xludf.DUMMYFUNCTION("""COMPUTED_VALUE"""),"User") -> User | N9: =IFERROR(__xludf.DUMMYFUNCTION("""COMPUTED_VALUE"""),"Season") -> Season | O9: =IFERROR(__xludf.DUMMYFUNCTION("""COMPUTED_VALUE"""),"Year") -> Year | P9: =IFERROR(__xludf.DUMMYFUNCTION("""COMPUTED_VALUE"""),"Solo") -> Solo
A10: =IFERROR(__xludf.DUMMYFUNCTION("""COMPUTED_VALUE"""),"QB") -> QB | B10: =IFERROR(__xludf.DUMMYFUNCTION("""COMPUTED_VALUE"""),"Marino") -> Marino | C10: =IFERROR(__xludf.DUMMYFUNCTION("""COMPUTED_VALUE"""),"Dan") -> Dan | D10: =IFERROR(__xludf.DUMMYFUNCTION("""COMPUTED_VALUE"""),277.0) -> 277 | E10: =IFERROR(__xludf.DUMMYFUNCTION("""COMPUTED_VALUE"""),229.0) -> 229 | F10: =IFERROR(__xludf.DUMMYFUNCTION("""COMPUTED_VALUE"""),82.6) -> 82.6 | G10: =IFERROR(__xludf.DUMMYFUNCTION("""COMPUTED_VALUE"""),6743.0) -> 6743 | H10: =IFERROR(__xludf.DUMMYFUNCTION("""COMPUTED_VALUE"""),24.3) -> 24.3 | I10: =IFERROR(__xludf.DUMMYFUNCTION("""COMPUTED_VALUE"""),110.0) -> 110 | J10: =IFERROR(__xludf.DUMMYFUNCTION("""COMPUTED_VALUE"""),0.0) -> 0 | K10: =IFERROR(__xludf.DUMMYFUNCTION("""COMPUTED_VALUE"""),248.1) -> 248.1 | L10: =IFERROR(__xludf.DUMMYFUNCTION("""COMPUTED_VALUE"""),"MIA") -> MIA | M10: =IFERROR(__xludf.DUMMYFUNCTION("""COMPUTED_VALUE"""),"CJ") -> CJ | N10: =IFERROR(__xludf.DUMMYFUNCTION("""COMPUTED_VALUE"""),13.0) -> 13 | O10: =IFERROR(__xludf.DUMMYFUNCTION("""COMPUTED_VALUE"""),2021.0) -> 2021 | P10: =IFERROR(__xludf.DUMMYFUNCTION("""COMPUTED_VALUE"""),"No") -> No
A11: =IFERROR(__xludf.DUMMYFUNCTION("""COMPUTED_VALUE"""),"QB") -> QB | B11: =IFERROR(__xludf.DUMMYFUNCTION("""COMPUTED_VALUE"""),"Marino") -> Marino | C11: =IFERROR(__xludf.DUMMYFUNCTION("""COMPUTED_VALUE"""),"Dan") -> Dan | D11: =IFERROR(__xludf.DUMMYFUNCTION("""COMPUTED_VALUE"""),249.0) -> 249 | E11: =IFERROR(__xludf.DUMMYFUNCTION("""COMPUTED_VALUE"""),217.0) -> 217 | F11: =IFERROR(__xludf.DUMMYFUNCTION("""COMPUTED_VALUE"""),87.1) -> 87.1 | G11: =IFERROR(__xludf.DUMMYFUNCTION("""COMPUTED_VALUE"""),5129.0) -> 5129 | H11: =IFERROR(__xludf.DUMMYFUNCTION("""COMPUTED_VALUE"""),20.6) -> 20.6 | I11: =IFERROR(__xludf.DUMMYFUNCTION("""COMPUTED_VALUE"""),65.0) -> 65 | J11: =IFERROR(__xludf.DUMMYFUNCTION("""COMPUTED_VALUE"""),2.0) -> 2 | K11: =IFERROR(__xludf.DUMMYFUNCTION("""COMPUTED_VALUE"""),241.5) -> 241.5 | L11: =IFERROR(__xludf.DUMMYFUNCTION("""COMPUTED_VALUE"""),"MIA") -> MIA | M11: =IFERROR(__xludf.DUMMYFUNCTION("""COMPUTED_VALUE"""),"MA") -> MA | N11: =IFERROR(__xludf.DUMMYFUNCTION("""COMPUTED_VALUE"""),17.0) -> 17 | O11: =IFERROR(__xludf.DUMMYFUNCTION("""COMPUTED_VALUE"""),2025.0) -> 2025 | P11: =IFERROR(__xludf.DUMMYFUNCTION("""COMPUTED_VALUE"""),"No") -> No
A12: =IFERROR(__xludf.DUMMYFUNCTION("""COMPUTED_VALUE"""),"QB") -> QB | B12: =IFERROR(__xludf.DUMMYFUNCTION("""COMPUTED_VALUE"""),"Moon") -> Moon | C12: =IFERROR(__xludf.DUMMYFUNCTION("""COMPUTED_VALUE"""),"Warren") -> Warren | D12: =IFERROR(__xludf.DUMMYFUNCTION("""COMPUTED_VALUE"""),316.0) -> 316 | E12: =IFERROR(__xludf.DUMMYFUNCTION("""COMPUTED_VALUE"""),200.0) -> 200 | F12: =IFERROR(__xludf.DUMMYFUNCTION("""COMPUTED_VALUE"""),63.2) -> 63.2 | G12: =IFERROR(__xludf.DUMMYFUNCTION("""COMPUTED_VALUE"""),6365.0) -> 6365 | H12: =IFERROR(__xludf.DUMMYFUNCTION("""COMPUTED_VALUE"""),20.1) -> 20.1 | I12: =IFERROR(__xludf.DUMMYFUNCTION("""COMPUTED_VALUE"""),80.0) -> 80 | J12: =IFERROR(__xludf.DUMMYFUNCTION("""COMPUTED_VALUE"""),6.0) -> 6 | K12: =IFERROR(__xludf.DUMMYFUNCTION("""COMPUTED_VALUE"""),197.2) -> 197.2 | L12: =IFERROR(__xludf.DUMMYFUNCTION("""COMPUTED_VALUE"""),"HOU") -> HOU | M12: =IFERROR(__xludf.DUMMYFUNCTION("""COMPUTED_VALUE"""),"WB") -> WB | N12: =IFERROR(__xludf.DUMMYFUNCTION("""COMPUTED_VALUE"""),6.0) -> 6 | O12: =IFERROR(__xludf.DUMMYFUNCTION("""COMPUTED_VALUE"""),2011.0) -> 2011 | P12: =IFERROR(__xludf.DUMMYFUNCTION("""COMPUTED_VALUE"""),"No") -> No
A14: Highest Completion %
A15: =IFERROR(__xludf.DUMMYFUNCTION("query(Passing!A2:P178, ""select * where P = 'No' order by F desc limit 3"",1)"),"POS") -> POS | B15: =IFERROR(__xludf.DUMMYFUNCTION("""COMPUTED_VALUE"""),"Last Name") -> Last Name | C15: =IFERROR(__xludf.DUMMYFUNCTION("""COMPUTED_VALUE"""),"First Name") -> First Name | D15: =IFERROR(__xludf.DUMMYFUNCTION("""COMPUTED_VALUE"""),"ATT") -> ATT | E15: =IFERROR(__xludf.DUMMYFUNCTION("""COMPUTED_VALUE"""),"COMPS") -> COMPS | F15: =IFERROR(__xludf.DUMMYFUNCTION("""COMPUTED_VALUE"""),"COMP %") -> COMP % | G15: =IFERROR(__xludf.DUMMYFUNCTION("""COMPUTED_VALUE"""),"YDS") -> YDS | H15: =IFERROR(__xludf.DUMMYFUNCTION("""COMPUTED_VALUE"""),"AVG YDS") -> AVG YDS | I15: =IFERROR(__xludf.DUMMYFUNCTION("""COMPUTED_VALUE"""),"TD") -> TD | J15: =IFERROR(__xludf.DUMMYFUNCTION("""COMPUTED_VALUE"""),"INT") -> INT | K15: =IFERROR(__xludf.DUMMYFUNCTION("""COMPUTED_VALUE"""),"RATING") -> RATING | L15: =IFERROR(__xludf.DUMMYFUNCTION("""COMPUTED_VALUE"""),"Team") -> Team | M15: =IFERROR(__xludf.DUMMYFUNCTION("""COMPUTED_VALUE"""),"User") -> User | N15: =IFERROR(__xludf.DUMMYFUNCTION("""COMPUTED_VALUE"""),"Season") -> Season | O15: =IFERROR(__xludf.DUMMYFUNCTION("""COMPUTED_VALUE"""),"Year") -> Year | P15: =IFERROR(__xludf.DUMMYFUNCTION("""COMPUTED_VALUE"""),"Solo") -> Solo
A16: =IFERROR(__xludf.DUMMYFUNCTION("""COMPUTED_VALUE"""),"QB") -> QB | B16: =IFERROR(__xludf.DUMMYFUNCTION("""COMPUTED_VALUE"""),"Marino") -> Marino | C16: =IFERROR(__xludf.DUMMYFUNCTION("""COMPUTED_VALUE"""),"Dan") -> Dan | D16: =IFERROR(__xludf.DUMMYFUNCTION("""COMPUTED_VALUE"""),249.0) -> 249 | E16: =IFERROR(__xludf.DUMMYFUNCTION("""COMPUTED_VALUE"""),217.0) -> 217 | F16: =IFERROR(__xludf.DUMMYFUNCTION("""COMPUTED_VALUE"""),87.1) -> 87.1 | G16: =IFERROR(__xludf.DUMMYFUNCTION("""COMPUTED_VALUE"""),5129.0) -> 5129 | H16: =IFERROR(__xludf.DUMMYFUNCTION("""COMPUTED_VALUE"""),20.6) -> 20.6 | I16: =IFERROR(__xludf.DUMMYFUNCTION("""COMPUTED_VALUE"""),65.0) -> 65 | J16: =IFERROR(__xludf.DUMMYFUNCTION("""COMPUTED_VALUE"""),2.0) -> 2 | K16: =IFERROR(__xludf.DUMMYFUNCTION("""COMPUTED_VALUE"""),241.5) -> 241.5 | L16: =IFERROR(__xludf.DUMMYFUNCTION("""COMPUTED_VALUE"""),"MIA") -> MIA | M16: =IFERROR(__xludf.DUMMYFUNCTION("""COMPUTED_VALUE"""),"MA") -> MA | N16: =IFERROR(__xludf.DUMMYFUNCTION("""COMPUTED_VALUE"""),17.0) -> 17 | O16: =IFERROR(__xludf.DUMMYFUNCTION("""COMPUTED_VALUE"""),2025.0) -> 2025 | P16: =IFERROR(__xludf.DUMMYFUNCTION("""COMPUTED_VALUE"""),"No") -> No
A17: =IFERROR(__xludf.DUMMYFUNCTION("""COMPUTED_VALUE"""),"QB") -> QB | B17: =IFERROR(__xludf.DUMMYFUNCTION("""COMPUTED_VALUE"""),"Marino") -> Marino | C17: =IFERROR(__xludf.DUMMYFUNCTION("""COMPUTED_VALUE"""),"Dan") -> Dan | D17: =IFERROR(__xludf.DUMMYFUNCTION("""COMPUTED_VALUE"""),277.0) -> 277 | E17: =IFERROR(__xludf.DUMMYFUNCTION("""COMPUTED_VALUE"""),229.0) -> 229 | F17: =IFERROR(__xludf.DUMMYFUNCTION("""COMPUTED_VALUE"""),82.6) -> 82.6 | G17: =IFERROR(__xludf.DUMMYFUNCTION("""COMPUTED_VALUE"""),6743.0) -> 6743 | H17: =IFERROR(__xludf.DUMMYFUNCTION("""COMPUTED_VALUE"""),24.3) -> 24.3 | I17: =IFERROR(__xludf.DUMMYFUNCTION("""COMPUTED_VALUE"""),110.0) -> 110 | J17: =IFERROR(__xludf.DUMMYFUNCTION("""COMPUTED_VALUE"""),0.0) -> 0 | K17: =IFERROR(__xludf.DUMMYFUNCTION("""COMPUTED_VALUE"""),248.1) -> 248.1 | L17: =IFERROR(__xludf.DUMMYFUNCTION("""COMPUTED_VALUE"""),"MIA") -> MIA | M17: =IFERROR(__xludf.DUMMYFUNCTION("""COMPUTED_VALUE"""),"CJ") -> CJ | N17: =IFERROR(__xludf.DUMMYFUNCTION("""COMPUTED_VALUE"""),13.0) -> 13 | O17: =IFERROR(__xludf.DUMMYFUNCTION("""COMPUTED_VALUE"""),2021.0) -> 2021 | P17: =IFERROR(__xludf.DUMMYFUNCTION("""COMPUTED_VALUE"""),"No") -> No
A18: =IFERROR(__xludf.DUMMYFUNCTION("""COMPUTED_VALUE"""),"QB") -> QB | B18: =IFERROR(__xludf.DUMMYFUNCTION("""COMPUTED_VALUE"""),"Esiason") -> Esiason | C18: =IFERROR(__xludf.DUMMYFUNCTION("""COMPUTED_VALUE"""),"Boomer") -> Boomer | D18: =IFERROR(__xludf.DUMMYFUNCTION("""COMPUTED_VALUE"""),144.0) -> 144 | E18: =IFERROR(__xludf.DUMMYFUNCTION("""COMPUTED_VALUE"""),117.0) -> 117 | F18: =IFERROR(__xludf.DUMMYFUNCTION("""COMPUTED_VALUE"""),81.2) -> 81.2 | G18: =IFERROR(__xludf.DUMMYFUNCTION("""COMPUTED_VALUE"""),2810.0) -> 2810 | H18: =IFERROR(__xludf.DUMMYFUNCTION("""COMPUTED_VALUE"""),19.5) -> 19.5 | I18: =IFERROR(__xludf.DUMMYFUNCTION("""COMPUTED_VALUE"""),36.0) -> 36 | J18: =IFERROR(__xludf.DUMMYFUNCTION("""COMPUTED_VALUE"""),2.0) -> 2 | K18: =IFERROR(__xludf.DUMMYFUNCTION("""COMPUTED_VALUE"""),228.6) -> 228.6 | L18: =IFERROR(__xludf.DUMMYFUNCTION("""COMPUTED_VALUE"""),"CIN") -> CIN | M18: =IFERROR(__xludf.DUMMYFUNCTION("""COMPUTED_VALUE"""),"PJ") -> PJ | N18: =IFERROR(__xludf.DUMMYFUNCTION("""COMPUTED_VALUE"""),11.0) -> 11 | O18: =IFERROR(__xludf.DUMMYFUNCTION("""COMPUTED_VALUE"""),2019.0) -> 2019 | P18: =IFERROR(__xludf.DUMMYFUNCTION("""COMPUTED_VALUE"""),"No") -> No
A20: Most Passing Yards
A21: =IFERROR(__xludf.DUMMYFUNCTION("query(Passing!A2:P178, ""select * where P = 'No' order by G desc limit 3"",1)"),"POS") -> POS | B21: =IFERROR(__xludf.DUMMYFUNCTION("""COMPUTED_VALUE"""),"Last Name") -> Last Name | C21: =IFERROR(__xludf.DUMMYFUNCTION("""COMPUTED_VALUE"""),"First Name") -> First Name | D21: =IFERROR(__xludf.DUMMYFUNCTION("""COMPUTED_VALUE"""),"ATT") -> ATT | E21: =IFERROR(__xludf.DUMMYFUNCTION("""COMPUTED_VALUE"""),"COMPS") -> COMPS | F21: =IFERROR(__xludf.DUMMYFUNCTION("""COMPUTED_VALUE"""),"COMP %") -> COMP % | G21: =IFERROR(__xludf.DUMMYFUNCTION("""COMPUTED_VALUE"""),"YDS") -> YDS | H21: =IFERROR(__xludf.DUMMYFUNCTION("""COMPUTED_VALUE"""),"AVG YDS") -> AVG YDS | I21: =IFERROR(__xludf.DUMMYFUNCTION("""COMPUTED_VALUE"""),"TD") -> TD | J21: =IFERROR(__xludf.DUMMYFUNCTION("""COMPUTED_VALUE"""),"INT") -> INT | K21: =IFERROR(__xludf.DUMMYFUNCTION("""COMPUTED_VALUE"""),"RATING") -> RATING | L21: =IFERROR(__xludf.DUMMYFUNCTION("""COMPUTED_VALUE"""),"Team") -> Team | M21: =IFERROR(__xludf.DUMMYFUNCTION("""COMPUTED_VALUE"""),"User") -> User | N21: =IFERROR(__xludf.DUMMYFUNCTION("""COMPUTED_VALUE"""),"Season") -> Season | O21: =IFERROR(__xludf.DUMMYFUNCTION("""COMPUTED_VALUE"""),"Year") -> Year | P21: =IFERROR(__xludf.DUMMYFUNCTION("""COMPUTED_VALUE"""),"Solo") -> Solo
A22: =IFERROR(__xludf.DUMMYFUNCTION("""COMPUTED_VALUE"""),"QB") -> QB | B22: =IFERROR(__xludf.DUMMYFUNCTION("""COMPUTED_VALUE"""),"Marino") -> Marino | C22: =IFERROR(__xludf.DUMMYFUNCTION("""COMPUTED_VALUE"""),"Dan") -> Dan | D22: =IFERROR(__xludf.DUMMYFUNCTION("""COMPUTED_VALUE"""),277.0) -> 277 | E22: =IFERROR(__xludf.DUMMYFUNCTION("""COMPUTED_VALUE"""),229.0) -> 229 | F22: =IFERROR(__xludf.DUMMYFUNCTION("""COMPUTED_VALUE"""),82.6) -> 82.6 | G22: =IFERROR(__xludf.DUMMYFUNCTION("""COMPUTED_VALUE"""),6743.0) -> 6743 | H22: =IFERROR(__xludf.DUMMYFUNCTION("""COMPUTED_VALUE"""),24.3) -> 24.3 | I22: =IFERROR(__xludf.DUMMYFUNCTION("""COMPUTED_VALUE"""),110.0) -> 110 | J22: =IFERROR(__xludf.DUMMYFUNCTION("""COMPUTED_VALUE"""),0.0) -> 0 | K22: =IFERROR(__xludf.DUMMYFUNCTION("""COMPUTED_VALUE"""),248.1) -> 248.1 | L22: =IFERROR(__xludf.DUMMYFUNCTION("""COMPUTED_VALUE"""),"MIA") -> MIA | M22: =IFERROR(__xludf.DUMMYFUNCTION("""COMPUTED_VALUE"""),"CJ") -> CJ | N22: =IFERROR(__xludf.DUMMYFUNCTION("""COMPUTED_VALUE"""),13.0) -> 13 | O22: =IFERROR(__xludf.DUMMYFUNCTION("""COMPUTED_VALUE"""),2021.0) -> 2021 | P22: =IFERROR(__xludf.DUMMYFUNCTION("""COMPUTED_VALUE"""),"No") -> No
A23: =IFERROR(__xludf.DUMMYFUNCTION("""COMPUTED_VALUE"""),"QB") -> QB | B23: =IFERROR(__xludf.DUMMYFUNCTION("""COMPUTED_VALUE"""),"Moon") -> Moon | C23: =IFERROR(__xludf.DUMMYFUNCTION("""COMPUTED_VALUE"""),"Warren") -> Warren | D23: =IFERROR(__xludf.DUMMYFUNCTION("""COMPUTED_VALUE"""),316.0) -> 316 | E23: =IFERROR(__xludf.DUMMYFUNCTION("""COMPUTED_VALUE"""),200.0) -> 200 | F23: =IFERROR(__xludf.DUMMYFUNCTION("""COMPUTED_VALUE"""),63.2) -> 63.2 | G23: =IFERROR(__xludf.DUMMYFUNCTION("""COMPUTED_VALUE"""),6365.0) -> 6365 | H23: =IFERROR(__xludf.DUMMYFUNCTION("""COMPUTED_VALUE"""),20.1) -> 20.1 | I23: =IFERROR(__xludf.DUMMYFUNCTION("""COMPUTED_VALUE"""),80.0) -> 80 | J23: =IFERROR(__xludf.DUMMYFUNCTION("""COMPUTED_VALUE"""),6.0) -> 6 | K23: =IFERROR(__xludf.DUMMYFUNCTION("""COMPUTED_VALUE"""),197.2) -> 197.2 | L23: =IFERROR(__xludf.DUMMYFUNCTION("""COMPUTED_VALUE"""),"HOU") -> HOU | M23: =IFERROR(__xludf.DUMMYFUNCTION("""COMPUTED_VALUE"""),"WB") -> WB | N23: =IFERROR(__xludf.DUMMYFUNCTION("""COMPUTED_VALUE"""),6.0) -> 6 | O23: =IFERROR(__xludf.DUMMYFUNCTION("""COMPUTED_VALUE"""),2011.0) -> 2011 | P23: =IFERROR(__xludf.DUMMYFUNCTION("""COMPUTED_VALUE"""),"No") -> No
A24: =IFERROR(__xludf.DUMMYFUNCTION("""COMPUTED_VALUE"""),"QB") -> QB | B24: =IFERROR(__xludf.DUMMYFUNCTION("""COMPUTED_VALUE"""),"Moon") -> Moon | C24: =IFERROR(__xludf.DUMMYFUNCTION("""COMPUTED_VALUE"""),"Warren") -> Warren | D24: =IFERROR(__xludf.DUMMYFUNCTION("""COMPUTED_VALUE"""),305.0) -> 305 | E24: =IFERROR(__xludf.DUMMYFUNCTION("""COMPUTED_VALUE"""),183.0) -> 183 | F24: =IFERROR(__xludf.DUMMYFUNCTION("""COMPUTED_VALUE"""),60.0) -> 60 | G24: =IFERROR(__xludf.DUMMYFUNCTION("""COMPUTED_VALUE"""),5822.0) -> 5822 | H24: =IFERROR(__xludf.DUMMYFUNCTION("""COMPUTED_VALUE"""),19.0) -> 19 | I24: =IFERROR(__xludf.DUMMYFUNCTION("""COMPUTED_VALUE"""),73.0) -> 73 | J24: =IFERROR(__xludf.DUMMYFUNCTION("""COMPUTED_VALUE"""),11.0) -> 11 | K24: =IFERROR(__xludf.DUMMYFUNCTION("""COMPUTED_VALUE"""),185.4) -> 185.4 | L24: =IFERROR(__xludf.DUMMYFUNCTION("""COMPUTED_VALUE"""),"HOU") -> HOU | M24: =IFERROR(__xludf.DUMMYFUNCTION("""COMPUTED_VALUE"""),"WB") -> WB | N24: =IFERROR(__xludf.DUMMYFUNCTION("""COMPUTED_VALUE"""),10.0) -> 10 | O24: =IFERROR(__xludf.DUMMYFUNCTION("""COMPUTED_VALUE"""),2018.0) -> 2018 | P24: =IFERROR(__xludf.DUMMYFUNCTION("""COMPUTED_VALUE"""),"No") -> No
A26: Highest Yards Per Attempt
A27: =IFERROR(__xludf.DUMMYFUNCTION("query(Passing!A2:P178, ""select * where P = 'No' order by H desc limit 3"",1)"),"POS") -> POS | B27: =IFERROR(__xludf.DUMMYFUNCTION("""COMPUTED_VALUE"""),"Last Name") -> Last Name | C27: =IFERROR(__xludf.DUMMYFUNCTION("""COMPUTED_VALUE"""),"First Name") -> First Name | D27: =IFERROR(__xludf.DUMMYFUNCTION("""COMPUTED_VALUE"""),"ATT") -> ATT | E27: =IFERROR(__xludf.DUMMYFUNCTION("""COMPUTED_VALUE"""),"COMPS") -> COMPS | F27: =IFERROR(__xludf.DUMMYFUNCTION("""COMPUTED_VALUE"""),"COMP %") -> COMP % | G27: =IFERROR(__xludf.DUMMYFUNCTION("""COMPUTED_VALUE"""),"YDS") -> YDS | H27: =IFERROR(__xludf.DUMMYFUNCTION("""COMPUTED_VALUE"""),"AVG YDS") -> AVG YDS | I27: =IFERROR(__xludf.DUMMYFUNCTION("""COMPUTED_VALUE"""),"TD") -> TD | J27: =IFERROR(__xludf.DUMMYFUNCTION("""COMPUTED_VALUE"""),"INT") -> INT | K27: =IFERROR(__xludf.DUMMYFUNCTION("""COMPUTED_VALUE"""),"RATING") -> RATING | L27: =IFERROR(__xludf.DUMMYFUNCTION("""COMPUTED_VALUE"""),"Team") -> Team | M27: =IFERROR(__xludf.DUMMYFUNCTION("""COMPUTED_VALUE"""),"User") -> User | N27: =IFERROR(__xludf.DUMMYFUNCTION("""COMPUTED_VALUE"""),"Season") -> Season | O27: =IFERROR(__xludf.DUMMYFUNCTION("""COMPUTED_VALUE"""),"Year") -> Year | P27: =IFERROR(__xludf.DUMMYFUNCTION("""COMPUTED_VALUE"""),"Solo") -> Solo
A28: =IFERROR(__xludf.DUMMYFUNCTION("""COMPUTED_VALUE"""),"QB") -> QB | B28: =IFERROR(__xludf.DUMMYFUNCTION("""COMPUTED_VALUE"""),"Marino") -> Marino | C28: =IFERROR(__xludf.DUMMYFUNCTION("""COMPUTED_VALUE"""),"Dan") -> Dan | D28: =IFERROR(__xludf.DUMMYFUNCTION("""COMPUTED_VALUE"""),144.0) -> 144 | E28: =IFERROR(__xludf.DUMMYFUNCTION("""COMPUTED_VALUE"""),113.0) -> 113 | F28: =IFERROR(__xludf.DUMMYFUNCTION("""COMPUTED_VALUE"""),78.4) -> 78.4 | G28: =IFERROR(__xludf.DUMMYFUNCTION("""COMPUTED_VALUE"""),3710.0) -> 3710 | H28: =IFERROR(__xludf.DUMMYFUNCTION("""COMPUTED_VALUE"""),25.7) -> 25.7 | I28: =IFERROR(__xludf.DUMMYFUNCTION("""COMPUTED_VALUE"""),45.0) -> 45 | J28: =IFERROR(__xludf.DUMMYFUNCTION("""COMPUTED_VALUE"""),3.0) -> 3 | K28: =IFERROR(__xludf.DUMMYFUNCTION("""COMPUTED_VALUE"""),270.3) -> 270.3 | L28: =IFERROR(__xludf.DUMMYFUNCTION("""COMPUTED_VALUE"""),"MIA") -> MIA | M28: =IFERROR(__xludf.DUMMYFUNCTION("""COMPUTED_VALUE"""),"MA") -> MA | N28: =IFERROR(__xludf.DUMMYFUNCTION("""COMPUTED_VALUE"""),7.0) -> 7 | O28: =IFERROR(__xludf.DUMMYFUNCTION("""COMPUTED_VALUE"""),2017.0) -> 2017 | P28: =IFERROR(__xludf.DUMMYFUNCTION("""COMPUTED_VALUE"""),"No") -> No
A29: =IFERROR(__xludf.DUMMYFUNCTION("""COMPUTED_VALUE"""),"QB") -> QB | B29: =IFERROR(__xludf.DUMMYFUNCTION("""COMPUTED_VALUE"""),"Ken") -> Ken | C29: =IFERROR(__xludf.DUMMYFUNCTION("""COMPUTED_VALUE"""),"OBrien") -> OBrien | D29: =IFERROR(__xludf.DUMMYFUNCTION("""COMPUTED_VALUE"""),172.0) -> 172 | E29: =IFERROR(__xludf.DUMMYFUNCTION("""COMPUTED_VALUE"""),127.0) -> 127 | F29: =IFERROR(__xludf.DUMMYFUNCTION("""COMPUTED_VALUE"""),73.8) -> 73.8 | G29: =IFERROR(__xludf.DUMMYFUNCTION("""COMPUTED_VALUE"""),4413.0) -> 4413 | H29: =IFERROR(__xludf.DUMMYFUNCTION("""COMPUTED_VALUE"""),25.6) -> 25.6 | I29: =IFERROR(__xludf.DUMMYFUNCTION("""COMPUTED_VALUE"""),45.0) -> 45 | J29: =IFERROR(__xludf.DUMMYFUNCTION("""COMPUTED_VALUE"""),1.0) -> 1 | K29: =IFERROR(__xludf.DUMMYFUNCTION("""COMPUTED_VALUE"""),255.3) -> 255.3 | L29: =IFERROR(__xludf.DUMMYFUNCTION("""COMPUTED_VALUE"""),"JET") -> JET | M29: =IFERROR(__xludf.DUMMYFUNCTION("""COMPUTED_VALUE"""),"CJ") -> CJ | N29: =IFERROR(__xludf.DUMMYFUNCTION("""COMPUTED_VALUE"""),9.0) -> 9 | O29: =IFERROR(__xludf.DUMMYFUNCTION("""COMPUTED_VALUE"""),2017.0) -> 2017 | P29: =IFERROR(__xludf.DUMMYFUNCTION("""COMPUTED_VALUE"""),"No") -> No
A30: =IFERROR(__xludf.DUMMYFUNCTION("""COMPUTED_VALUE"""),"QB") -> QB | B30: =IFERROR(__xludf.DUMMYFUNCTION("""COMPUTED_VALUE"""),"Simms") -> Simms | C30: =IFERROR(__xludf.DUMMYFUNCTION("""COMPUTED_VALUE"""),"Phil") -> Phil | D30: =IFERROR(__xludf.DUMMYFUNCTION("""COMPUTED_VALUE"""),182.0) -> 182 | E30: =IFERROR(__xludf.DUMMYFUNCTION("""COMPUTED_VALUE"""),133.0) -> 133 | F30: =IFERROR(__xludf.DUMMYFUNCTION("""COMPUTED_VALUE"""),73.0) -> 73 | G30: =IFERROR(__xludf.DUMMYFUNCTION("""COMPUTED_VALUE"""),4629.0) -> 4629 | H30: =IFERROR(__xludf.DUMMYFUNCTION("""COMPUTED_VALUE"""),25.4) -> 25.4 | I30: =IFERROR(__xludf.DUMMYFUNCTION("""COMPUTED_VALUE"""),63.0) -> 63 | J30: =IFERROR(__xludf.DUMMYFUNCTION("""COMPUTED_VALUE"""),6.0) -> 6 | K30: =IFERROR(__xludf.DUMMYFUNCTION("""COMPUTED_VALUE"""),270.6) -> 270.6 | L30: =IFERROR(__xludf.DUMMYFUNCTION("""COMPUTED_VALUE"""),"GIA") -> GIA | M30: =IFERROR(__xludf.DUMMYFUNCTION("""COMPUTED_VALUE"""),"PJ") -> PJ | N30: =IFERROR(__xludf.DUMMYFUNCTION("""COMPUTED_VALUE"""),7.0) -> 7 | O30: =IFERROR(__xludf.DUMMYFUNCTION("""COMPUTED_VALUE"""),2017.0) -> 2017 | P30: =IFERROR(__xludf.DUMMYFUNCTION("""COMPUTED_VALUE"""),"No") -> No
A32: Most Passing Touchdowns
A33: =IFERROR(__xludf.DUMMYFUNCTION("query(Passing!A2:P178, ""select * where P = 'No' order by I desc limit 3"",1)"),"POS") -> POS | B33: =IFERROR(__xludf.DUMMYFUNCTION("""COMPUTED_VALUE"""),"Last Name") -> Last Name | C33: =IFERROR(__xludf.DUMMYFUNCTION("""COMPUTED_VALUE"""),"First Name") -> First Name | D33: =IFERROR(__xludf.DUMMYFUNCTION("""COMPUTED_VALUE"""),"ATT") -> ATT | E33: =IFERROR(__xludf.DUMMYFUNCTION("""COMPUTED_VALUE"""),"COMPS") -> COMPS | F33: =IFERROR(__xludf.DUMMYFUNCTION("""COMPUTED_VALUE"""),"COMP %") -> COMP % | G33: =IFERROR(__xludf.DUMMYFUNCTION("""COMPUTED_VALUE"""),"YDS") -> YDS | H33: =IFERROR(__xludf.DUMMYFUNCTION("""COMPUTED_VALUE"""),"AVG YDS") -> AVG YDS | I33: =IFERROR(__xludf.DUMMYFUNCTION("""COMPUTED_VALUE"""),"TD") -> TD | J33: =IFERROR(__xludf.DUMMYFUNCTION("""COMPUTED_VALUE"""),"INT") -> INT | K33: =IFERROR(__xludf.DUMMYFUNCTION("""COMPUTED_VALUE"""),"RATING") -> RATING | L33: =IFERROR(__xludf.DUMMYFUNCTION("""COMPUTED_VALUE"""),"Team") -> Team | M33: =IFERROR(__xludf.DUMMYFUNCTION("""COMPUTED_VALUE"""),"User") -> User | N33: =IFERROR(__xludf.DUMMYFUNCTION("""COMPUTED_VALUE"""),"Season") -> Season | O33: =IFERROR(__xludf.DUMMYFUNCTION("""COMPUTED_VALUE"""),"Year") -> Year | P33: =IFERROR(__xludf.DUMMYFUNCTION("""COMPUTED_VALUE"""),"Solo") -> Solo
A34: =IFERROR(__xludf.DUMMYFUNCTION("""COMPUTED_VALUE"""),"QB") -> QB | B34: =IFERROR(__xludf.DUMMYFUNCTION("""COMPUTED_VALUE"""),"Marino") -> Marino | C34: =IFERROR(__xludf.DUMMYFUNCTION("""COMPUTED_VALUE"""),"Dan") -> Dan | D34: =IFERROR(__xludf.DUMMYFUNCTION("""COMPUTED_VALUE"""),277.0) -> 277 | E34: =IFERROR(__xludf.DUMMYFUNCTION("""COMPUTED_VALUE"""),229.0) -> 229 | F34: =IFERROR(__xludf.DUMMYFUNCTION("""COMPUTED_VALUE"""),82.6) -> 82.6 | G34: =IFERROR(__xludf.DUMMYFUNCTION("""COMPUTED_VALUE"""),6743.0) -> 6743 | H34: =IFERROR(__xludf.DUMMYFUNCTION("""COMPUTED_VALUE"""),24.3) -> 24.3 | I34: =IFERROR(__xludf.DUMMYFUNCTION("""COMPUTED_VALUE"""),110.0) -> 110 | J34: =IFERROR(__xludf.DUMMYFUNCTION("""COMPUTED_VALUE"""),0.0) -> 0 | K34: =IFERROR(__xludf.DUMMYFUNCTION("""COMPUTED_VALUE"""),248.1) -> 248.1 | L34: =IFERROR(__xludf.DUMMYFUNCTION("""COMPUTED_VALUE"""),"MIA") -> MIA | M34: =IFERROR(__xludf.DUMMYFUNCTION("""COMPUTED_VALUE"""),"CJ") -> CJ | N34: =IFERROR(__xludf.DUMMYFUNCTION("""COMPUTED_VALUE"""),13.0) -> 13 | O34: =IFERROR(__xludf.DUMMYFUNCTION("""COMPUTED_VALUE"""),2021.0) -> 2021 | P34: =IFERROR(__xludf.DUMMYFUNCTION("""COMPUTED_VALUE"""),"No") -> No
A35: =IFERROR(__xludf.DUMMYFUNCTION("""COMPUTED_VALUE"""),"QB") -> QB | B35: =IFERROR(__xludf.DUMMYFUNCTION("""COMPUTED_VALUE"""),"Moon") -> Moon | C35: =IFERROR(__xludf.DUMMYFUNCTION("""COMPUTED_VALUE"""),"Warren") -> Warren | D35: =IFERROR(__xludf.DUMMYFUNCTION("""COMPUTED_VALUE"""),316.0) -> 316 | E35: =IFERROR(__xludf.DUMMYFUNCTION("""COMPUTED_VALUE"""),200.0) -> 200 | F35: =IFERROR(__xludf.DUMMYFUNCTION("""COMPUTED_VALUE"""),63.2) -> 63.2 | G35: =IFERROR(__xludf.DUMMYFUNCTION("""COMPUTED_VALUE"""),6365.0) -> 6365 | H35: =IFERROR(__xludf.DUMMYFUNCTION("""COMPUTED_VALUE"""),20.1) -> 20.1 | I35: =IFERROR(__xludf.DUMMYFUNCTION("""COMPUTED_VALUE"""),80.0) -> 80 | J35: =IFERROR(__xludf.DUMMYFUNCTION("""COMPUTED_VALUE"""),6.0) -> 6 | K35: =IFERROR(__xludf.DUMMYFUNCTION("""COMPUTED_VALUE"""),197.2) -> 197.2 | L35: =IFERROR(__xludf.DUMMYFUNCTION("""COMPUTED_VALUE"""),"HOU") -> HOU | M35: =IFERROR(__xludf.DUMMYFUNCTION("""COMPUTED_VALUE"""),"WB") -> WB | N35: =IFERROR(__xludf.DUMMYFUNCTION("""COMPUTED_VALUE"""),6.0) -> 6 | O35: =IFERROR(__xludf.DUMMYFUNCTION("""COMPUTED_VALUE"""),2011.0) -> 2011 | P35: =IFERROR(__xludf.DUMMYFUNCTION("""COMPUTED_VALUE"""),"No") -> No
A36: =IFERROR(__xludf.DUMMYFUNCTION("""COMPUTED_VALUE"""),"QB") -> QB | B36: =IFERROR(__xludf.DUMMYFUNCTION("""COMPUTED_VALUE"""),"Moon") -> Moon | C36: =IFERROR(__xludf.DUMMYFUNCTION("""COMPUTED_VALUE"""),"Warren") -> Warren | D36: =IFERROR(__xludf.DUMMYFUNCTION("""COMPUTED_VALUE"""),305.0) -> 305 | E36: =IFERROR(__xludf.DUMMYFUNCTION("""COMPUTED_VALUE"""),183.0) -> 183 | F36: =IFERROR(__xludf.DUMMYFUNCTION("""COMPUTED_VALUE"""),60.0) -> 60 | G36: =IFERROR(__xludf.DUMMYFUNCTION("""COMPUTED_VALUE"""),5822.0) -> 5822 | H36: =IFERROR(__xludf.DUMMYFUNCTION("""COMPUTED_VALUE"""),19.0) -> 19 | I36: =IFERROR(__xludf.DUMMYFUNCTION("""COMPUTED_VALUE"""),73.0) -> 73 | J36: =IFERROR(__xludf.DUMMYFUNCTION("""COMPUTED_VALUE"""),11.0) -> 11 | K36: =IFERROR(__xludf.DUMMYFUNCTION("""COMPUTED_VALUE"""),185.4) -> 185.4 | L36: =IFERROR(__xludf.DUMMYFUNCTION("""COMPUTED_VALUE"""),"HOU") -> HOU | M36: =IFERROR(__xludf.DUMMYFUNCTION("""COMPUTED_VALUE"""),"WB") -> WB | N36: =IFERROR(__xludf.DUMMYFUNCTION("""COMPUTED_VALUE"""),10.0) -> 10 | O36: =IFERROR(__xludf.DUMMYFUNCTION("""COMPUTED_VALUE"""),2018.0) -> 2018 | P36: =IFERROR(__xludf.DUMMYFUNCTION("""COMPUTED_VALUE"""),"No") -> No
A38: Fewest Interceptions
A39: =IFERROR(__xludf.DUMMYFUNCTION("query(Passing!A2:P178, ""select * where P = 'No' order by J asc limit 3"",1)"),"POS") -> POS | B39: =IFERROR(__xludf.DUMMYFUNCTION("""COMPUTED_VALUE"""),"Last Name") -> Last Name | C39: =IFERROR(__xludf.DUMMYFUNCTION("""COMPUTED_VALUE"""),"First Name") -> First Name | D39: =IFERROR(__xludf.DUMMYFUNCTION("""COMPUTED_VALUE"""),"ATT") -> ATT | E39: =IFERROR(__xludf.DUMMYFUNCTION("""COMPUTED_VALUE"""),"COMPS") -> COMPS | F39: =IFERROR(__xludf.DUMMYFUNCTION("""COMPUTED_VALUE"""),"COMP %") -> COMP % | G39: =IFERROR(__xludf.DUMMYFUNCTION("""COMPUTED_VALUE"""),"YDS") -> YDS | H39: =IFERROR(__xludf.DUMMYFUNCTION("""COMPUTED_VALUE"""),"AVG YDS") -> AVG YDS | I39: =IFERROR(__xludf.DUMMYFUNCTION("""COMPUTED_VALUE"""),"TD") -> TD | J39: =IFERROR(__xludf.DUMMYFUNCTION("""COMPUTED_VALUE"""),"INT") -> INT | K39: =IFERROR(__xludf.DUMMYFUNCTION("""COMPUTED_VALUE"""),"RATING") -> RATING | L39: =IFERROR(__xludf.DUMMYFUNCTION("""COMPUTED_VALUE"""),"Team") -> Team | M39: =IFERROR(__xludf.DUMMYFUNCTION("""COMPUTED_VALUE"""),"User") -> User | N39: =IFERROR(__xludf.DUMMYFUNCTION("""COMPUTED_VALUE"""),"Season") -> Season | O39: =IFERROR(__xludf.DUMMYFUNCTION("""COMPUTED_VALUE"""),"Year") -> Year | P39: =IFERROR(__xludf.DUMMYFUNCTION("""COMPUTED_VALUE"""),"Solo") -> Solo
A40: =IFERROR(__xludf.DUMMYFUNCTION("""COMPUTED_VALUE"""),"QB") -> QB | B40: =IFERROR(__xludf.DUMMYFUNCTION("""COMPUTED_VALUE"""),"Marino") -> Marino | C40: =IFERROR(__xludf.DUMMYFUNCTION("""COMPUTED_VALUE"""),"Dan") -> Dan | D40: =IFERROR(__xludf.DUMMYFUNCTION("""COMPUTED_VALUE"""),277.0) -> 277 | E40: =IFERROR(__xludf.DUMMYFUNCTION("""COMPUTED_VALUE"""),229.0) -> 229 | F40: =IFERROR(__xludf.DUMMYFUNCTION("""COMPUTED_VALUE"""),82.6) -> 82.6 | G40: =IFERROR(__xludf.DUMMYFUNCTION("""COMPUTED_VALUE"""),6743.0) -> 6743 | H40: =IFERROR(__xludf.DUMMYFUNCTION("""COMPUTED_VALUE"""),24.3) -> 24.3 | I40: =IFERROR(__xludf.DUMMYFUNCTION("""COMPUTED_VALUE"""),110.0) -> 110 | J40: =IFERROR(__xludf.DUMMYFUNCTION("""COMPUTED_VALUE"""),0.0) -> 0 | K40: =IFERROR(__xludf.DUMMYFUNCTION("""COMPUTED_VALUE"""),248.1) -> 248.1 | L40: =IFERROR(__xludf.DUMMYFUNCTION("""COMPUTED_VALUE"""),"MIA") -> MIA | M40: =IFERROR(__xludf.DUMMYFUNCTION("""COMPUTED_VALUE"""),"CJ") -> CJ | N40: =IFERROR(__xludf.DUMMYFUNCTION("""COMPUTED_VALUE"""),13.0) -> 13 | O40: =IFERROR(__xludf.DUMMYFUNCTION("""COMPUTED_VALUE"""),2021.0) -> 2021 | P40: =IFERROR(__xludf.DUMMYFUNCTION("""COMPUTED_VALUE"""),"No") -> No
A41: =IFERROR(__xludf.DUMMYFUNCTION("""COMPUTED_VALUE"""),"QB") -> QB | B41: =IFERROR(__xludf.DUMMYFUNCTION("""COMPUTED_VALUE"""),"Everett") -> Everett | C41: =IFERROR(__xludf.DUMMYFUNCTION("""COMPUTED_VALUE"""),"Jim") -> Jim | I41: =IFERROR(__xludf.DUMMYFUNCTION("""COMPUTED_VALUE"""),59.0) -> 59 | J41: =IFERROR(__xludf.DUMMYFUNCTION("""COMPUTED_VALUE"""),1.0) -> 1 | K41: =IFERROR(__xludf.DUMMYFUNCTION("""COMPUTED_VALUE"""),219.2) -> 219.2 | L41: =IFERROR(__xludf.DUMMYFUNCTION("""COMPUTED_VALUE"""),"RAM") -> RAM | M41: =IFERROR(__xludf.DUMMYFUNCTION("""COMPUTED_VALUE"""),"PJ") -> PJ | N41: =IFERROR(__xludf.DUMMYFUNCTION("""COMPUTED_VALUE"""),3.0) -> 3 | O41: =IFERROR(__xludf.DUMMYFUNCTION("""COMPUTED_VALUE"""),2009.0) -> 2009 | P41: =IFERROR(__xludf.DUMMYFUNCTION("""COMPUTED_VALUE"""),"No") -> No
A42: =IFERROR(__xludf.DUMMYFUNCTION("""COMPUTED_VALUE"""),"QB") -> QB | B42: =IFERROR(__xludf.DUMMYFUNCTION("""COMPUTED_VALUE"""),"Ken") -> Ken | C42: =IFERROR(__xludf.DUMMYFUNCTION("""COMPUTED_VALUE"""),"OBrien") -> OBrien | D42: =IFERROR(__xludf.DUMMYFUNCTION("""COMPUTED_VALUE"""),172.0) -> 172 | E42: =IFERROR(__xludf.DUMMYFUNCTION("""COMPUTED_VALUE"""),127.0) -> 127 | F42: =IFERROR(__xludf.DUMMYFUNCTION("""COMPUTED_VALUE"""),73.8) -> 73.8 | G42: =IFERROR(__xludf.DUMMYFUNCTION("""COMPUTED_VALUE"""),4413.0) -> 4413 | H42: =IFERROR(__xludf.DUMMYFUNCTION("""COMPUTED_VALUE"""),25.6) -> 25.6 | I42: =IFERROR(__xludf.DUMMYFUNCTION("""COMPUTED_VALUE"""),45.0) -> 45 | J42: =IFERROR(__xludf.DUMMYFUNCTION("""COMPUTED_VALUE"""),1.0) -> 1 | K42: =IFERROR(__xludf.DUMMYFUNCTION("""COMPUTED_VALUE"""),255.3) -> 255.3 | L42: =IFERROR(__xludf.DUMMYFUNCTION("""COMPUTED_VALUE"""),"JET") -> JET | M42: =IFERROR(__xludf.DUMMYFUNCTION("""COMPUTED_VALUE"""),"CJ") -> CJ | N42: =IFERROR(__xludf.DUMMYFUNCTION("""COMPUTED_VALUE"""),9.0) -> 9 | O42: =IFERROR(__xludf.DUMMYFUNCTION("""COMPUTED_VALUE"""),2017.0) -> 2017 | P42: =IFERROR(__xludf.DUMMYFUNCTION("""COMPUTED_VALUE"""),"No") -> No
A44: Highest QB Rating
A45: =IFERROR(__xludf.DUMMYFUNCTION("query(Passing!A2:P178, ""select * where P = 'No' order by K desc limit 3"",1)"),"POS") -> POS | B45: =IFERROR(__xludf.DUMMYFUNCTION("""COMPUTED_VALUE"""),"Last Name") -> Last Name | C45: =IFERROR(__xludf.DUMMYFUNCTION("""COMPUTED_VALUE"""),"First Name") -> First Name | D45: =IFERROR(__xludf.DUMMYFUNCTION("""COMPUTED_VALUE"""),"ATT") -> ATT | E45: =IFERROR(__xludf.DUMMYFUNCTION("""COMPUTED_VALUE"""),"COMPS") -> COMPS | F45: =IFERROR(__xludf.DUMMYFUNCTION("""COMPUTED_VALUE"""),"COMP %") -> COMP % | G45: =IFERROR(__xludf.DUMMYFUNCTION("""COMPUTED_VALUE"""),"YDS") -> YDS | H45: =IFERROR(__xludf.DUMMYFUNCTION("""COMPUTED_VALUE"""),"AVG YDS") -> AVG YDS | I45: =IFERROR(__xludf.DUMMYFUNCTION("""COMPUTED_VALUE"""),"TD") -> TD | J45: =IFERROR(__xludf.DUMMYFUNCTION("""COMPUTED_VALUE"""),"INT") -> INT | K45: =IFERROR(__xludf.DUMMYFUNCTION("""COMPUTED_VALUE"""),"RATING") -> RATING | L45: =IFERROR(__xludf.DUMMYFUNCTION("""COMPUTED_VALUE"""),"Team") -> Team | M45: =IFERROR(__xludf.DUMMYFUNCTION("""COMPUTED_VALUE"""),"User") -> User | N45: =IFERROR(__xludf.DUMMYFUNCTION("""COMPUTED_VALUE"""),"Season") -> Season | O45: =IFERROR(__xludf.DUMMYFUNCTION("""COMPUTED_VALUE"""),"Year") -> Year | P45: =IFERROR(__xludf.DUMMYFUNCTION("""COMPUTED_VALUE"""),"Solo") -> Solo
A46: =IFERROR(__xludf.DUMMYFUNCTION("""COMPUTED_VALUE"""),"QB") -> QB | B46: =IFERROR(__xludf.DUMMYFUNCTION("""COMPUTED_VALUE"""),"Simms") -> Simms | C46: =IFERROR(__xludf.DUMMYFUNCTION("""COMPUTED_VALUE"""),"Phil") -> Phil | D46: =IFERROR(__xludf.DUMMYFUNCTION("""COMPUTED_VALUE"""),182.0) -> 182 | E46: =IFERROR(__xludf.DUMMYFUNCTION("""COMPUTED_VALUE"""),133.0) -> 133 | F46: =IFERROR(__xludf.DUMMYFUNCTION("""COMPUTED_VALUE"""),73.0) -> 73 | G46: =IFERROR(__xludf.DUMMYFUNCTION("""COMPUTED_VALUE"""),4629.0) -> 4629 | H46: =IFERROR(__xludf.DUMMYFUNCTION("""COMPUTED_VALUE"""),25.4) -> 25.4 | I46: =IFERROR(__xludf.DUMMYFUNCTION("""COMPUTED_VALUE"""),63.0) -> 63 | J46: =IFERROR(__xludf.DUMMYFUNCTION("""COMPUTED_VALUE"""),6.0) -> 6 | K46: =IFERROR(__xludf.DUMMYFUNCTION("""COMPUTED_VALUE"""),270.6) -> 270.6 | L46: =IFERROR(__xludf.DUMMYFUNCTION("""COMPUTED_VALUE"""),"GIA") -> GIA | M46: =IFERROR(__xludf.DUMMYFUNCTION("""COMPUTED_VALUE"""),"PJ") -> PJ | N46: =IFERROR(__xludf.DUMMYFUNCTION("""COMPUTED_VALUE"""),7.0) -> 7 | O46: =IFERROR(__xludf.DUMMYFUNCTION("""COMPUTED_VALUE"""),2017.0) -> 2017 | P46: =IFERROR(__xludf.DUMMYFUNCTION("""COMPUTED_VALUE"""),"No") -> No
A47: =IFERROR(__xludf.DUMMYFUNCTION("""COMPUTED_VALUE"""),"QB") -> QB | B47: =IFERROR(__xludf.DUMMYFUNCTION("""COMPUTED_VALUE"""),"Marino") -> Marino | C47: =IFERROR(__xludf.DUMMYFUNCTION("""COMPUTED_VALUE"""),"Dan") -> Dan | D47: =IFERROR(__xludf.DUMMYFUNCTION("""COMPUTED_VALUE"""),144.0) -> 144 | E47: =IFERROR(__xludf.DUMMYFUNCTION("""COMPUTED_VALUE"""),113.0) -> 113 | F47: =IFERROR(__xludf.DUMMYFUNCTION("""COMPUTED_VALUE"""),78.4) -> 78.4 | G47: =IFERROR(__xludf.DUMMYFUNCTION("""COMPUTED_VALUE"""),3710.0) -> 3710 | H47: =IFERROR(__xludf.DUMMYFUNCTION("""COMPUTED_VALUE"""),25.7) -> 25.7 | I47: =IFERROR(__xludf.DUMMYFUNCTION("""COMPUTED_VALUE"""),45.0) -> 45 | J47: =IFERROR(__xludf.DUMMYFUNCTION("""COMPUTED_VALUE"""),3.0) -> 3 | K47: =IFERROR(__xludf.DUMMYFUNCTION("""COMPUTED_VALUE"""),270.3) -> 270.3 | L47: =IFERROR(__xludf.DUMMYFUNCTION("""COMPUTED_VALUE"""),"MIA") -> MIA | M47: =IFERROR(__xludf.DUMMYFUNCTION("""COMPUTED_VALUE"""),"MA") -> MA | N47: =IFERROR(__xludf.DUMMYFUNCTION("""COMPUTED_VALUE"""),7.0) -> 7 | O47: =IFERROR(__xludf.DUMMYFUNCTION("""COMPUTED_VALUE"""),2017.0) -> 2017 | P47: =IFERROR(__xludf.DUMMYFUNCTION("""COMPUTED_VALUE"""),"No") -> No
...

Sheet Passing
A1: TECMO PASSING STATISTICS
A2: POS | B2: Last Name | C2: First Name | D2: ATT | E2: COMPS | F2: COMP % | G2: YDS | H2: AVG YDS | I2: TD | J2: INT | K2: RATING | L2: Team | M2: User | N2: Season | O2: Year | P2: Solo
A3: QB | B3: Marino | C3: Dan | I3: 63 | J3: 4 | K3: 227.4 | L3: MIA | M3: PJ | N3: 1 | O3: =vlookup(N3,Superbowls!$A$2:$B$115,2,FALSE) -> 2009 | P3: No
A4: QB | B4: Schroeder | C4: Jay | I4: 15 | J4: 16 | K4: 70.4 | L4: RAI | M4: MA | N4: 1 | O4: =vlookup(N4,Superbowls!$A$2:$B$115,2,FALSE) -> 2009 | P4: No
A5: QB | B5: Peete | C5: Rodney | I5: 28 | J5: 8 | K5: 164.9 | L5: DET | M5: PJ | N5: 2 | O5: =vlookup(N5,Superbowls!$A$2:$B$115,2,FALSE) -> 2009 | P5: No
A6: QB | B6: Moon | C6: Warren | I6: 40 | J6: 5 | K6: 130.5 | L6: HOU | M6: WB | N6: 2 | O6: =vlookup(N6,Superbowls!$A$2:$B$115,2,FALSE) -> 2009 | P6: No
A7: QB | B7: Everett | C7: Jim | I7: 59 | J7: 1 | K7: 219.2 | L7: RAM | M7: PJ | N7: 3 | O7: =vlookup(N7,Superbowls!$A$2:$B$115,2,FALSE) -> 2009 | P7: No
A8: QB | B8: Moon | C8: Warren | D8: 272 | E8: 153 | F8: 56.2 | G8: 5170 | H8: 19 | I8: 65 | J8: 5 | K8: 197.6 | L8: HOU | M8: WB | N8: 4 | O8: =vlookup(N8,Superbowls!$A$2:$B$115,2,FALSE) -> 2009 | P8: No
A9: QB | B9: Eagles | C9: QB | D9: 242 | E9: 129 | F9: 53.3 | G9: 2985 | H9: 12.3 | I9: 33 | J9: 14 | K9: 119.2 | L9: PHI | M9: CR | N9: 4 | O9: =vlookup(N9,Superbowls!$A$2:$B$115,2,FALSE) -> 2009 | P9: No
A10: QB | B10: Testaverde | C10: Vinny | D10: 239 | E10: 171 | F10: 71.5 | G10: 4873 | H10: 20.3 | I10: 60 | J10: 11 | K10: 211.1 | L10: TB | M10: PJ | N10: 4 | O10: =vlookup(N10,Superbowls!$A$2:$B$115,2,FALSE) -> 2009 | P10: No
A11: QB | B11: Bills | C11: QB | D11: 211 | E11: 148 | F11: 70.1 | G11: 5136 | H11: 24.3 | I11: 56 | J11: 6 | K11: 238.5 | L11: BUF | M11: CR | N11: 5 | O11: =vlookup(N11,Superbowls!$A$2:$B$115,2,FALSE) -> 2010 | P11: No
A12: QB | B12: Simms | C12: Phil | D12: 195 | E12: 143 | F12: 73.3 | G12: 4696 | H12: 24 | I12: 66 | J12: 6 | K12: 258.4 | L12: GIA | M12: PJ | N12: 5 | O12: =vlookup(N12,Superbowls!$A$2:$B$115,2,FALSE) -> 2010 | P12: No
A13: QB | B13: Moon | C13: Warren | D13: 316 | E13: 200 | F13: 63.2 | G13: 6365 | H13: 20.1 | I13: 80 | J13: 6 | K13: 197.2 | L13: HOU | M13: WB | N13: 6 | O13: =vlookup(N13,Superbowls!$A$2:$B$115,2,FALSE) -> 2011 | P13: No
A14: QB | B14: Wilson | C14: Marc | D14: 232 | E14: 160 | F14: 68.9 | G14: 4082 | H14: 17.5 | I14: 41 | J14: 8 | K14: 177.4 | L14: NE | M14: PJ | N14: 6 | O14: =vlookup(N14,Superbowls!$A$2:$B$115,2,FALSE) -> 2011 | P14: No
A15: QB | B15: Simms | C15: Phil | D15: 182 | E15: 133 | F15: 73 | G15: 4629 | H15: 25.4 | I15: 63 | J15: 6 | K15: 270.6 | L15: GIA | M15: PJ | N15: 7 | O15: =vlookup(N15,Superbowls!$A$2:$B$115,2,FALSE) -> 2017 | P15: No
A16: QB | B16: Marino | C16: Dan | D16: 144 | E16: 113 | F16: 78.4 | G16: 3710 | H16: 25.7 | I16: 45 | J16: 3 | K16: 270.3 | L16: MIA | M16: MA | N16: 7 | O16: =vlookup(N16,Superbowls!$A$2:$B$115,2,FALSE) -> 2017 | P16: No
A17: QB | B17: Krieg | C17: Dave | D17: 264 | E17: 166 | F17: 62.8 | G17: 4269 | H17: 16.1 | I17: 44 | J17: 15 | K17: 153.7 | L17: SEA | M17: WB | N17: 7 | O17: =vlookup(N17,Superbowls!$A$2:$B$115,2,FALSE) -> 2017 | P17: No
A18: QB | B18: Testaverde | C18: Vinny | D18: 133 | E18: 95 | F18: 71.4 | G18: 3097 | H18: 23.2 | I18: 34 | J18: 6 | K18: 225 | L18: TB | M18: CJ | N18: 8 | O18: =vlookup(N18,Superbowls!$A$2:$B$115,2,FALSE) -> 2017 | P18: No
A19: QB | B19: Rypien | C19: Mark | D19: 155 | E19: 101 | F19: 65.1 | G19: 3286 | H19: 21.2 | I19: 38 | J19: 8 | K19: 204.9 | L19: WAS | M19: WB | N19: 8 | O19: =vlookup(N19,Superbowls!$A$2:$B$115,2,FALSE) -> 2017 | P19: No
... A52: QB | B52: Brister | C52: Bubby | D52: 87 | E52: 57 | F52: 65.5 | G52: 1384 | H52: 15.9 | I52: 13 | J52: 3 | K52: 158.4 | L52: PIT | M52: PJ | N52: 15 | O52: =vlookup(N52,Superbowls!$A$2:$B$115,2,FALSE) -> 2023 | P52: No
A53: QB | B53: Bills | C53: QB | D53: 109 | E53: 88 | F53: 80.7 | G53: 2493 | H53: 22.8 | I53: 25 | J53: 1 | K53: 237.2 | L53: BUF | M53: PJ | N53: 16 | O53: 2024 | P53: No
A54: QB | B54: Grogan | C54: Steve | D54: 87 | E54: 52 | F54: 59.7 | G54: 1377 | H54: 15.8 | I54: 13 | J54: 9 | K54: 124.5 | L54: NE | M54: CR | N54: 16 | O54: 2024 | P54: No
A55: QB | B55: Wilson | C55: Marc | D55: 112 | E55: 66 | F55: 58.9 | G55: 1823 | H55: 16.2 | I55: 16 | J55: 10 | K55: 129.4 | L55: NE | M55: CR | N55: 16 | O55: 2024 | P55: No
A56: QB | B56: O.Brien | C56: Ken | D56: 195 | E56: 139 | F56: 71.2 | G56: 3236 | H56: 16.5 | I56: 36 | J56: 6 | K56: 179.3 | L56: JET | M56: MA | N56: 16 | O56: 2024 | P56: No
A57: QB | B57: Simms | C57: Phil | D57: 188 | E57: 109 | F57: 57.4 | G57: 3460 | H57: 18.4 | I57: 30 | J57: 13 | K57: 151.4 | L57: GIA | M57: BF | N57: 16 | O57: 2024 | P57: No
A58: QB | B58: Rosenbach | C58: Timm | D58: 80 | E58: 49 | F58: 61.2 | G58: 1282 | H58: 16 | I58: 17 | J58: 7 | K58: 154.2 | L58: PHX | M58: WB | N58: 16 | O58: 2024 | P58: No
A59: QB | B59: Bills | C59: QB | D59: 266 | E59: 181 | F59: 68 | G59: 4643 | H59: 17.4 | I59: 44 | J59: 4 | K59: 180.3 | L59: BUF | M59: MAE | N59: 17 | O59: 2025 | P59: No
A60: QB | B60: Marino | C60: Dan | D60: 249 | E60: 217 | F60: 87.1 | G60: 5129 | H60: 20.6 | I60: 65 | J60: 2 | K60: 241.5 | L60: MIA | M60: MA | N60: 17 | O60: 2025 | P60: No
A61: QB | B61: Bills | C61: QB | D61: 258 | E61: 191 | F61: 74 | G61: 4919 | H61: 19 | I61: 67 | J61: 2 | K61: 221.3 | L61: BUF | M61: MAE | N61: 18 | O61: 2025 | P61: No
A62: QB | B62: Everett | C62: Jim | D62: 200 | E62: 162 | F62: 81 | G62: 4206 | H62: 21 | I62: 49 | J62: 3 | K62: 232.6 | L62: RAM | M62: MA | N62: 18 | O62: 2025 | P62: No
A63: QB | B63: Bills | C63: QB | D63: 263 | E63: 196 | F63: 74.5 | G63: 4955 | H63: 18.8 | I63: 50 | J63: 5 | K63: 198.1 | L63: BUF | M63: MAE | N63: 19 | O63: 2025 | P63: No
A64: QB | B64: Peete | C64: Rodney | D64: 52 | E64: 34 | F64: 65.3 | G64: 892 | H64: 17.1 | I64: 5 | J64: 3 | K64: 136 | L64: DET | M64: MA | N64: 19 | O64: 2025 | P64: No
... A68: QB | B68: Eagles | C68: QB | D68: 210 | E68: 118 | F68: 56.1 | G68: 2997 | H68: 14.2 | I68: 25 | J68: 12 | K68: 124.2 | L68: PHI | M68: AD | N68: 21 | O68: 2026 | P68: No

Sheet Receiving
A1: TECMO RECEIVING STATISTICS
A2: POS | B2: Last Name | C2: First Name | D2: REC | E2: YDS | F2: AVG YDS | G2: TDs | H2: Team | I2: User | J2: Season | K2: Year | L2: Solo
A3: WR | B3: Duper | C3: Mark | D3: 45 | E3: 1665 | F3: =1665/45 -> 37 | G3: 26 | H3: MIA | I3: PJ | J3: 1 | K3: =vlookup(J3,Superbowls!$A$2:$B$115,2,FALSE) -> 2009 | L3: No
A4: RB | B4: Paige | C4: Tony | D4: 41 | E4: 709 | F4: =709/41 -> 17.292683 | G4: 12 | H4: MIA | I4: PJ | J4: 1 | K4: =vlookup(J4,Superbowls!$A$2:$B$115,2,FALSE) -> 2009 | L4: No
A5: TE | B5: Edmunds | C5: Ferrell | D5: 40 | E5: 878 | F5: =878/40 -> 21.95 | G5: 10 | H5: MIA | I5: PJ | J5: 1 | K5: =vlookup(J5,Superbowls!$A$2:$B$115,2,FALSE) -> 2009 | L5: No
A6: WR | B6: Givins | C6: Ernest | D6: 38 | E6: 941 | F6: =941/38 -> 24.763158 | G6: 10 | H6: HOU | I6: WB | J6: 2 | K6: =vlookup(J6,Superbowls!$A$2:$B$115,2,FALSE) -> 2009 | L6: No
A7: WR | B7: Jeffries | C7: Haywood | D7: 37 | E7: 1186 | F7: =1186/37 -> 32.054054 | G7: 19 | H7: HOU | I7: WB | J7: 2 | K7: =vlookup(J7,Superbowls!$A$2:$B$115,2,FALSE) -> 2009 | L7: No
A8: TE | B8: Holohan | C8: Pete | D8: 57 | E8: 738 | F8: =738/57 -> 12.947368 | G8: 11 | H8: RAM | I8: PJ | J8: 3 | K8: =vlookup(J8,Superbowls!$A$2:$B$115,2,FALSE) -> 2009 | L8: No
A9: WR | B9: Ellard | C9: Henry | D9: 43 | E9: 1643 | F9: =1643/43 -> 38.209302 | G9: 30 | H9: RAM | I9: PJ | J9: 3 | K9: =vlookup(J9,Superbowls!$A$2:$B$115,2,FALSE) -> 2009 | L9: No
A10: TE | B10: Jackson | C10: Keith | D10: 68 | E10: 1150 | F10: 16.9 | G10: 13 | H10: PHI | I10: CR | J10: 4 | K10: =vlookup(J10,Superbowls!$A$2:$B$115,2,FALSE) -> 2009 | L10: No
A11: WR | B11: Carrier | C11: Mark | D11: 60 | E11: 1412 | F11: 23.5 | G11: 17 | H11: TB | I11: PJ | J11: 4 | K11: =vlookup(J11,Superbowls!$A$2:$B$115,2,FALSE) -> 2009 | L11: No
A12: WR | B12: Givins | C12: Ernest | D12: 50 | E12: 2355 | F12: 47 | G12: 37 | H12: HOU | I12: WB | J12: 4 | K12: =vlookup(J12,Superbowls!$A$2:$B$115,2,FALSE) -> 2009 | L12: No
A13: WR | B13: Jeffries | C13: Haywood | D13: 47 | E13: 1131 | F13: 24.9 | G13: 11 | H13: HOU | I13: WB | J13: 4 | K13: =vlookup(J13,Superbowls!$A$2:$B$115,2,FALSE) -> 2009 | L13: No
A14: RB | B14: Cobb | C14: Reggie | D14: 43 | E14: 1560 | F14: 36.2 | G14: 18 | H14: TB | I14: PJ | J14: 4 | K14: =vlookup(J14,Superbowls!$A$2:$B$115,2,FALSE) -> 2009 | L14: No
A15: TE | B15: Hall | C15: Ron | D15: 26 | E15: 712 | F15: 19.7 | G15: 9 | H15: TB | I15: PJ | J15: 4 | K15: =vlookup(J15,Superbowls!$A$2:$B$115,2,FALSE) -> 2009 | L15: No
A16: WR | B16: Reed | C16: Andre | D16: 62 | E16: 3257 | F16: 52.5 | G16: 41 | H16: BUF | I16: CR | J16: 5 | K16: =vlookup(J16,Superbowls!$A$2:$B$115,2,FALSE) -> 2010 | L16: No
A17: WR | B17: Ingram | C17: Mark | D17: 38 | E17: 938 | F17: 24.6 | G17: 17 | H17: GIA | I17: PJ | J17: 5 | K17: =vlookup(J17,Superbowls!$A$2:$B$115,2,FALSE) -> 2010 | L17: No
A18: WR | B18: Baker | C18: Stephen | D18: 35 | E18: 1668 | F18: 47.6 | G18: 25 | H18: GIA | I18: PJ | J18: 5 | K18: =vlookup(J18,Superbowls!$A$2:$B$115,2,FALSE) -> 2010 | L18: No
A19: RB | B19: Megget | C19: Dave | D19: 34 | E19: 1463 | F19: 43 | G19: 19 | H19: GIA | I19: PJ | J19: 5 | K19: =vlookup(J19,Superbowls!$A$2:$B$115,2,FALSE) -> 2010 | L19: No
A20: WR | B20: Hill | C20: Drew | D20: 86 | E20: 3881 | F20: 45.1 | G20: 56 | H20: HOU | I20: WB | J20: 6 | K20: =vlookup(J20,Superbowls!$A$2:$B$115,2,FALSE) -> 2011 | L20: No
A21: TE | B21: Cook | C21: Marv | D21: 49 | E21: 902 | F21: 18.4 | G21: 7 | H21: NE | I21: PJ | J21: 6 | K21: =vlookup(J21,Superbowls!$A$2:$B$115,2,FALSE) -> 2011 | L21: No
... A41: WR | B41: Rice | C41: Jerry | D41: 70 | E41: 3287 | F41: 46.9 | G41: 46 | H41: SF | I41: TD | J41: 10 | K41: =vlookup(J41,Superbowls!$A$2:$B$115,2,FALSE) -> 2018 | L41: No
A42: TE | B42: McKeller | D42: 50 | E42: 1158 | F42: 23.1 | G42: 8 | H42: BUF | I42: CR | J42: 10 | K42: =vlookup(J42,Superbowls!$A$2:$B$115,2,FALSE) -> 2018 | L42: No
A43: WR | B43: Reed | C43: Andre | D43: 47 | E43: 2128 | F43: 45.2 | G43: 32 | H43: BUF | I43: CR | J43: 10 | K43: =vlookup(J43,Superbowls!$A$2:$B$115,2,FALSE) -> 2018 | L43: No
A44: TE | B44: Jackson | C44: Keith | D44: 45 | E44: 1084 | F44: 24 | G44: 14 | H44: PHI | I44: PJ | J44: 10 | K44: =vlookup(J44,Superbowls!$A$2:$B$115,2,FALSE) -> 2018 | L44: No
A45: TE | B45: Bavaro | C45: Mark | D45: 44 | E45: 805 | F45: 18.2 | G45: 6 | H45: GIA | I45: CJ | J45: 10 | K45: =vlookup(J45,Superbowls!$A$2:$B$115,2,FALSE) -> 2018 | L45: No
A46: TE | B46: Jones | C46: Brent | D46: 42 | E46: 646 | F46: 15.3 | G46: 10 | H46: SF | I46: TD | J46: 10 | K46: =vlookup(J46,Superbowls!$A$2:$B$115,2,FALSE) -> 2018 | L46: No
A47: RB | B47: Megget | C47: Dave | D47: 42 | E47: 1864 | F47: 44.3 | G47: 28 | H47: GIA | I47: CJ | J47: 10 | K47: =vlookup(J47,Superbowls!$A$2:$B$115,2,FALSE) -> 2018 | L47: No
A48: WR | B48: Ingram | C48: Mark | D48: 40 | E48: 1111 | F48: 27.7 | G48: 8 | H48: GIA | I48: CJ | J48: 10 | K48: =vlookup(J48,Superbowls!$A$2:$B$115,2,FALSE) -> 2018 | L48: No
A49: TE | B49: Holman | C49: Rodney | D49: 52 | E49: 1189 | F49: 22.8 | G49: 19 | H49: CIN | I49: PJ | J49: 11 | K49: =vlookup(J49,Superbowls!$A$2:$B$115,2,FALSE) -> 2019 | L49: No
A50: TE | B50: Thomas | C50: Robb | D50: 49 | E50: 943 | F50: 19.2 | G50: 8 | H50: KC | I50: CJ | J50: 11 | K50: =vlookup(J50,Superbowls!$A$2:$B$115,2,FALSE) -> 2019 | L50: No
A51: WR | B51: Clayton | C51: Mark | D51: 47 | E51: 1709 | F51: 36.3 | G51: 20 | H51: MIA | I51: WB | J51: 11 | K51: =vlookup(J51,Superbowls!$A$2:$B$115,2,FALSE) -> 2019 | L51: No
A52: RB | B52: Word | C52: Barry | D52: 43 | E52: 1566 | F52: 36.4 | G52: 14 | H52: KC | I52: CJ | J52: 11 | K52: =vlookup(J52,Superbowls!$A$2:$B$115,2,FALSE) -> 2019 | L52: No
A53: RB | B53: Sammie | C53: Smith | D53: 38 | E53: 365 | F53: 9.6 | G53: 3 | H53: MIA | I53: WB | J53: 11 | K53: =vlookup(J53,Superbowls!$A$2:$B$115,2,FALSE) -> 2019 | L53: No
A54: TE | B54: Brenner | C54: Hoby | D54: 33 | E54: 577 | F54: 17.4 | G54: 3 | H54: NO | I54: MA | J54: 11 | K54: =vlookup(J54,Superbowls!$A$2:$B$115,2,FALSE) -> 2019 | L54: No
... A98: TE | B98: Green | C98: Eric | D98: 16 | E98: 312 | F98: 19.5 | G98: 1 | H98: PIT | I98: PJ | J98: 15 | K98: =vlookup(J98,Superbowls!$A$2:$B$115,2,FALSE) -> 2023 | L98: No
A99: RB | B99: Thurman | C99: Thomas | D99: 13 | E99: 125 | F99: 9.6 | G99: 2 | H99: BUF | I99: PJ | J99: 16 | K99: 2024 | L99: No
A100: WR | B100: Mueller | C100: Jamie | D100: 12 | E100: 416 | F100: 34.6 | G100: 3 | H100: BUF | I100: PJ | J100: 16 | K100: 2024 | L100: No
A101: WR | B101: Lofton | C101: James | D101: 14 | E101: 456 | F101: 32.5 | G101: 7 | H101: BUF | I101: PJ | J101: 16 | K101: 2024 | L101: No
A102: WR | B102: Reed | C102: Andre | D102: 32 | E102: 1174 | F102: 36.6 | G102: 12 | H102: BUF | I102: PJ | J102: 16 | K102: 2024 | L102: No
...

Sheet Rushing
A1: TECMO RUSHING STATISTICS
A2: POS | B2: Last Name | C2: First Name | D2: ATT | E2: YDS | F2: AVG YDS | G2: TD | H2: Team | I2: User | J2: Season | K2: Year | L2: Solo
A3: RB | B3: Jackson | C3: Bo | D3: 130 | E3: 1417 | F3: =E3/D3 -> 10.9 | G3: 25 | H3: RAI | I3: MA | J3: 1 | K3: =vlookup(J3,Superbowls!$A$2:$B$115,2,FALSE) -> 2009 | L3: No
A4: RB | B4: Smith | C4: Emmitt | D4: 255 | E4: 2490 | F4: =E4/D4 -> 9.7647059 | G4: 40 | H4: DAL | I4: WB | J4: 1 | K4: =vlookup(J4,Superbowls!$A$2:$B$115,2,FALSE) -> 2009 | L4: No
A5: RB | B5: Allen | C5: Marcus | D5: 137 | E5: 1196 | F5: =E5/D5 -> 8.729927 | G5: 18 | H5: RAI | I5: MA | J5: 1 | K5: =vlookup(J5,Superbowls!$A$2:$B$115,2,FALSE) -> 2009 | L5: No
A6: RB | B6: Sanders | C6: Barry | D6: 164 | E6: 2132 | F6: =E6/D6 -> 13 | G6: 43 | H6: DET | I6: PJ | J6: 2 | K6: =vlookup(J6,Superbowls!$A$2:$B$115,2,FALSE) -> 2009 | L6: No
A7: RB | B7: Jackson | C7: Bo | D7: 247 | E7: 2936 | F7: =E7/D7 -> 11.88664 | G7: 56 | H7: RAI | I7: MA | J7: 3 | K7: =vlookup(J7,Superbowls!$A$2:$B$115,2,FALSE) -> 2009 | L7: No
A8: RB | B8: Okoye | C8: Christian | D8: 255 | E8: 2414 | F8: =E8/D8 -> 9.4666667 | G8: 43 | H8: KC | I8: WB | J8: 3 | K8: =vlookup(J8,Superbowls!$A$2:$B$115,2,FALSE) -> 2009 | L8: No
A9: QB | B9: Eagles | C9: QB | D9: 97 | E9: 1205 | F9: =E9/D9 -> 12.42268 | G9: 19 | H9: PHI | I9: CR | J9: 4 | K9: =vlookup(J9,Superbowls!$A$2:$B$115,2,FALSE) -> 2009 | L9: No
A10: RB | B10: Jackson | C10: Bo | D10: 200 | E10: 2252 | F10: =E10/D10 -> 11.26 | G10: 46 | H10: RAI | I10: MA | J10: 4 | K10: =vlookup(J10,Superbowls!$A$2:$B$115,2,FALSE) -> 2009 | L10: No
A11: RB | B11: Anderson | C11: Neal | D11: 255 | E11: 3294 | F11: 12.9 | G11: 68 | H11: CHI | I11: CJ | J11: 6 | K11: =vlookup(J11,Superbowls!$A$2:$B$115,2,FALSE) -> 2011 | L11: No
A12: RB | B12: Sanders | C12: Barry | D12: 188 | E12: 3554 | F12: 18.9 | G12: 58 | H12: DET | I12: CJ | J12: 7 | K12: =vlookup(J12,Superbowls!$A$2:$B$115,2,FALSE) -> 2017 | L12: No
A13: RB | B13: Byner | C13: Earnest | D13: 200 | E13: 895 | F13: 4.4 | G13: 16 | H13: WAS | I13: WB | J13: 8 | K13: =vlookup(J13,Superbowls!$A$2:$B$115,2,FALSE) -> 2017 | L13: No
A14: RB | B14: Anderson | C14: Gary | D14: 84 | E14: 685 | F14: 8.1 | G14: 17 | H14: TB | I14: CJ | J14: 8 | K14: =vlookup(J14,Superbowls!$A$2:$B$115,2,FALSE) -> 2017 | L14: No
A15: RB | B15: Butts | C15: Marion | D15: 173 | E15: 2138 | F15: 12.3 | G15: 40 | H15: SD | I15: PJ | J15: 9 | K15: =vlookup(J15,Superbowls!$A$2:$B$115,2,FALSE) -> 2017 | L15: No
A16: RB | B16: Bentley | C16: Albert | D16: 209 | E16: 1281 | F16: 6.1 | G16: 15 | H16: IND | I16: WB | J16: 9 | K16: =vlookup(J16,Superbowls!$A$2:$B$115,2,FALSE) -> 2017 | L16: No
A17: RB | B17: Thomas | C17: Blair | D17: 120 | E17: 750 | F17: 6.2 | G17: 25 | H17: JET | I17: CJ | J17: 9 | K17: =vlookup(J17,Superbowls!$A$2:$B$115,2,FALSE) -> 2017 | L17: No
A18: RB | B18: Jackson | C18: Bo | D18: 165 | E18: 2174 | F18: 13.1 | G18: 42 | H18: RAI | I18: MA | J18: 10 | K18: =vlookup(J18,Superbowls!$A$2:$B$115,2,FALSE) -> 2018 | L18: No
A19: RB | B19: Okoye | C19: Christian | D19: 103 | E19: 831 | F19: 8 | G19: 33 | H19: KC | I19: CJ | J19: 11 | K19: =vlookup(J19,Superbowls!$A$2:$B$115,2,FALSE) -> 2019 | L19: No
A20: RB | B20: Heyward | C20: Craig | D20: 57 | E20: 533 | F20: 9.3 | G20: 12 | H20: NO | I20: MA | J20: 11 | K20: =vlookup(J20,Superbowls!$A$2:$B$115,2,FALSE) -> 2019 | L20: No
A21: RB | B21: Brooks | C21: James | D21: 66 | E21: 453 | F21: 6.8 | G21: 17 | H21: CIN | I21: PJ | J21: 11 | K21: =vlookup(J21,Superbowls!$A$2:$B$115,2,FALSE) -> 2019 | L21: No
A22: RB | B22: Thomas | C22: Blair | D22: 80 | E22: 482 | F22: 6 | G22: 15 | H22: JET | I22: PJ | J22: 12 | K22: =vlookup(J22,Superbowls!$A$2:$B$115,2,FALSE) -> 2020 | L22: No
... A37: RB | B37: Hoge | C37: Merril | D37: 231 | E37: 1349 | F37: 5.8 | G37: 24 | H37: PIT | I37: MA | J37: 15 | K37: =vlookup(J37,Superbowls!$A$2:$B$115,2,FALSE) -> 2023 | L37: No
A38: QB | B38: Bills | C38: QB | D38: 40 | E38: 170 | F38: 4.2 | G38: 1 | H38: BUF | I38: PJ | J38: 16 | K38: 2024 | L38: No
A39: RB | B39: Thomas | C39: Thurman | D39: 184 | E39: 1984 | F39: 10.7 | G39: 51 | H39: BUF | I39: PJ | J39: 16 | K39: 2024 | L39: No
A40: RB | B40: Stephens | C40: John | D40: 97 | E40: 439 | F40: 4.5 | G40: 14 | H40: NE | I40: CR | J40: 16 | K40: 2024 | L40: No
A41: QB | B41: O.Brien | C41: Ken | D41: 44 | E41: 286 | F41: 6.5 | G41: 8 | H41: JET | I41: MA | J41: 16 | K41: 2024 | L41: No
A42: RB | B42: Thomas | C42: Blair | D42: 91 | E42: 438 | F42: 4.8 | G42: 8 | H42: JET | I42: MA | J42: 16 | K42: 2024 | L42: No
A43: RB | B43: McNeil | C43: Freeman | D43: 26 | E43: 217 | F43: 8.3 | G43: 2 | H43: JET | I43: MA | J43: 16 | K43: 2024 | L43: No
A44: RB | B44: Anderson | C44: Ottis | D44: 115 | E44: 980 | F44: 8.5 | G44: 23 | H44: GIA | I44: BF | J44: 16 | K44: 2024 | L44: No
A45: RB | B45: Meggett | C45: David | D45: 77 | E45: 485 | F45: 6.2 | G45: 12 | H45: GIA | I45: BF | J45: 16 | K45: 2024 | L45: No
A46: RB | B46: Johnson | C46: Johnny | D46: 225 | E46: 1409 | F46: 6.2 | G46: 22 | H46: PHX | I46: WB | J46: 16 | K46: 2024 | L46: No
A47: RB | B47: Sikahema | C47: Vai | D47: 46 | E47: 115 | F47: 2.5 | G47: 0 | H47: PHX | I47: WB | J47: 16 | K47: 2024 | L47: No
A48: QB | B48: Marino | C48: Dan | D48: 73 | E48: 302 | F48: 4.1 | G48: 8 | H48: MIA | I48: MA | J48: 17 | K48: 2025 | L48: No
A49: RB | B49: Smith | C49: Sammie | D49: 10 | E49: 49 | F49: 4.9 | G49: 2 | H49: MIA | I49: MA | J49: 17 | K49: 2025 | L49: No
... A72: RB | B72: Sherman | C72: Heath | D72: 50 | E72: 210 | F72: 4.2 | G72: 4 | H72: PHI | I72: AD | J72: 21 | K72: 2026 | L72: No

Sheet Scoring
A1: TECMO SCORING STATISTICS
A2: POS | B2: Last Name | C2: First Name | D2: POINTS | E2: Team | F2: User | G2: Season | H2: Year | I2: Solo
A3: RB | B3: Smith | C3: Emmitt | D3: 240 | E3: DAL | F3: WB | G3: 1 | H3: =vlookup(G3,Superbowls!$A$2:$B$115,2,FALSE) -> 2009 | I3: No
A4: WR | B4: Duper | C4: Mark | D4: 156 | E4: MIA | F4: PJ | G4: 1 | H4: =vlookup(G4,Superbowls!$A$2:$B$115,2,FALSE) -> 2009 | I4: No
A5: RB | B5: Jackson | C5: Bo | D5: 150 | E5: RAI | F5: MA | G5: 1 | H5: =vlookup(G5,Superbowls!$A$2:$B$115,2,FALSE) -> 2009 | I5: No
A6: RB | B6: Allen | C6: Marcus | D6: 126 | E6: RAI | F6: MA | G6: 1 | H6: =vlookup(G6,Superbowls!$A$2:$B$115,2,FALSE) -> 2009 | I6: No
A7: RB | B7: Paige | C7: Tony | D7: 126 | E7: MIA | F7: PJ | G7: 1 | H7: =vlookup(G7,Superbowls!$A$2:$B$115,2,FALSE) -> 2009 | I7: No
A8: K | B8: Stoyanovich | C8: Pete | D8: 103 | E8: MIA | F8: PJ | G8: 1 | H8: =vlookup(G8,Superbowls!$A$2:$B$115,2,FALSE) -> 2009 | I8: No
A9: WR | B9: Clayton | C9: Mark | D9: 90 | E9: MIA | F9: PJ | G9: 1 | H9: =vlookup(G9,Superbowls!$A$2:$B$115,2,FALSE) -> 2009 | I9: No
A10: RB | B10: Sanders | C10: Barry | D10: 258 | E10: DET | F10: PJ | G10: 2 | H10: =vlookup(G10,Superbowls!$A$2:$B$115,2,FALSE) -> 2009 | I10: No
A11: WR | B11: Jefferies | C11: Haywood | D11: 114 | E11: HOU | F11: PJ | G11: 2 | H11: =vlookup(G11,Superbowls!$A$2:$B$115,2,FALSE) -> 2009 | I11: No
A12: RB | B12: Jackson | C12: Bo | D12: 336 | E12: OAK | F12: MA | G12: 3 | H12: =vlookup(G12,Superbowls!$A$2:$B$115,2,FALSE) -> 2009 | I12: No
A13: RB | B13: Okoye | C13: Christian | D13: 258 | E13: KC | F13: WB | G13: 3 | H13: =vlookup(G13,Superbowls!$A$2:$B$115,2,FALSE) -> 2009 | I13: No
A14: WR | B14: Ellard | C14: Henry | D14: 180 | E14: RAM | F14: PJ | G14: 3 | H14: =vlookup(G14,Superbowls!$A$2:$B$115,2,FALSE) -> 2009 | I14: No
... A48: QB | B48: Eagles | C48: QB | D48: 138 | E48: PHI | F48: PJ | G48: 10 | H48: =vlookup(G48,Superbowls!$A$2:$B$115,2,FALSE) -> 2018 | I48: No
A49: WR | B49: Barnett | D49: 114 | E49: PHI | F49: PJ | G49: 10 | H49: =vlookup(G49,Superbowls!$A$2:$B$115,2,FALSE) -> 2018 | I49: No
A50: RB | B50: Okoye | C50: Christian | D50: 198 | E50: KC | F50: CJ | G50: 11 | H50: =vlookup(G50,Superbowls!$A$2:$B$115,2,FALSE) -> 2019 | I50: No
A51: WR | B51: Clayton | C51: Mark | D51: 120 | E51: MIA | F51: WB | G51: 11 | H51: =vlookup(G51,Superbowls!$A$2:$B$115,2,FALSE) -> 2019 | I51: No
A52: WR | B52: Paige | C52: Stephone | D52: 114 | E52: KC | F52: CJ | G52: 11 | H52: =vlookup(G52,Superbowls!$A$2:$B$115,2,FALSE) -> 2019 | I52: No
A53: TE | B53: Holman | C53: Rodney | D53: 114 | E53: CIN | F53: PJ | G53: 11 | H53: =vlookup(G53,Superbowls!$A$2:$B$115,2,FALSE) -> 2019 | I53: No
A54: RB | B54: Smith | C54: Sammie | D54: 108 | E54: MIA | F54: WB | G54: 11 | H54: =vlookup(G54,Superbowls!$A$2:$B$115,2,FALSE) -> 2019 | I54: No
A55: RB | B55: Brooks | C55: James | D55: 102 | E55: CIN | F55: PJ | G55: 11 | H55: =vlookup(G55,Superbowls!$A$2:$B$115,2,FALSE) -> 2019 | I55: No
A56: RB | B56: Humphrey | C56: Bobby | D56: 156 | E56: DEN | F56: CR | G56: 12 | H56: =vlookup(G56,Superbowls!$A$2:$B$115,2,FALSE) -> 2020 | I56: No
A57: RB | B57: Highsmith | C57: Alonzo | D57: 102 | E57: DAL | F57: CJ | G57: 12 | H57: =vlookup(G57,Superbowls!$A$2:$B$115,2,FALSE) -> 2020 | I57: No
A58: RB | B58: Hoge | C58: Merril | D58: 102 | E58: PIT | F58: WB | G58: 12 | H58: =vlookup(G58,Superbowls!$A$2:$B$115,2,FALSE) -> 2020 | I58: No
A59: K | B59: Leahy | D59: 100 | E59: JET | F59: PJ | G59: 12 | H59: =vlookup(G59,Superbowls!$A$2:$B$115,2,FALSE) -> 2020 | I59: No
A60: RB | B60: Jackson | C60: Bo | D60: =70*6 -> 420 | E60: RAI | F60: PJ | G60: 13 | H60: =vlookup(G60,Superbowls!$A$2:$B$115,2,FALSE) -> 2021 | I60: No
A61: WR | B61: Duper | C61: Mark | D61: 336 | E61: MIA | F61: CJ | G61: 13 | H61: =vlookup(G61,Superbowls!$A$2:$B$115,2,FALSE) -> 2021 | I61: No
